Workbook

Sheet IRFP4468PbF loss and tempurtur
A1: LOSS | B1: Name | C1: Homepage | D1: Vds max | E1: Id max (25®C) (Package Limited) | F1: Id max (25®C) | G1: Id max (100®C) | H1: Rds(on) Typ. | I1: Rds(on) max | J1: Input Capacitance Ciss max [pF] | K1: R j c max | L1: R c s | M1: House | N1: Pris(omkring 500 stk)
B2: IRFP4468PbF | C2: Rs.online | D2: 100 | E2: 195 | F2: 290 | G2: 200 | H2: 0.002 | I2: 0.0026 | J2: 19860 | K2: 0.29 | L2: 0.24 | M2: TO-247AC | N2: 36.13
A5: Current to the Motor
A6: Sinus peak | B6: 300 | C6: A
A7: Current RMS | B7: =B6/2^0.5 -> 212.13203 | C7: A, RMS
A9: MOSFET max rating
A10: Drain current in two MOSFET combined, RMS | B10: =B7/2^0.5 -> 150 | C10: A,RMS
A11: Drain current in one MOSFET, RMS | B11: =B10/2 -> 75 | C11: A, RMS
A12: Peak current in MOSFET | B12: =B6/2 -> 150 | C12: A
A13: Vbat | B13: 52.8 | C13: V
A14: Vds max rating | B14: 100 | C14: V
A18: Conduction loss
A19: Tempurtur junction (Tj) | B19: 100 | C19: °C
A20: Rds(on) faktor | B20: =0.8498*EXP(0.0066*B19) -> 1.6441865
A21: Rds(on) Typ. | B21: =H2 -> 0.002 | C21: Ω
A22: Rds(on) | B22: =B21*B20 -> 0.0032883731 | C22: Ω
A23: Pcon,Loss | B23: =B22*B11^2 -> 18.497098 | C23: W
A26: Switching loss
A27: Switching frequence | B27: 20000 | C27: Hz
A29: Total sw loss | B29: ='Swtching loss'!C89 -> 48.688757 | C29: W
A33: Total Loss in one MOSFET
A34: P loss, total | B34: =B29+B23 -> 67.185855 | C34: W
A38: Tempurtur
B40: Name | C40: Homepage | D40: Dimension | E40: Use with | F40: Number of MOSFET | G40: Therminal Resistor | H40: Power supply | I40: Pris for one
B41: SK 487/84 SA | C41: Rs.online | D41: 84 x 52.3 x 28mm | E41: TO-247, TO-220 | F41: About 2-3 | G41: 2.5 | H41: No | I41: 37.27
A44: Thermal capacitor
A45: Area | B45: =((0.008*0.028)+(0.028-0.0125)*0.042) -> 0.000875 | C45: m^2
A46: Length | B46: 0.084 | C46: m
A47: Volume | B47: =B46*B45 -> 7.35e-05 | C47: m^3
A49: Correction factor of the volume | B49: 2
A50: Real volume | B50: =B47/B49 -> 3.675e-05 | C50: m^3
A52: Density | B52: 2700 | C52: Kg/m^3
A53: Mass | B53: =B50*B52 -> 0.099225 | C53: Kg
A54: c alu | B54: 900 | C54: J/(°C*kg)
A55: Thermal capacitor (Cs) | B55: =B54*B53 -> 89.3025 | C55: J/°C
A59: Thermal resistor
A60: Rjc | B60: =K2 -> 0.29 | C60: °C/W
A61: Rcs | B61: =L2 -> 0.24 | C61: °C/W
A62: Rsa | B62: =G41 -> 2.5 | C62: °C/W
A66: Tempurtur MOSFET
...

Sheet Rds(on) vs. Tj
A1: -20 | B1: 0.75
A2: 25 | B2: 1
A3: 60 | B3: 1.25 | D3: Finding equation for RDS(on) vs. Tj
A4: 90 | B4: 1.5
A5: 100 | B5: 1.7

Sheet Swtching loss
A3: First off assum that Cgs is the same for on and off time. And it is equeal to Ciss at 50V
B5: Cgs | C5: =0.00000002 -> 2e-08 | D5: F
A21: Assum that the time Vds rise and fall is defined by the datasheet. See pictures
B23: t rise | C23: 2.3e-07 | D23: s
B24: t fall | C24: 2.6e-07 | D24: s
A36: Off time loss
A37: The time drain current fall is defined by Cgs and gate current | B37: I gate off | C37: =2.3/2 -> 1.15 | D37: A
A38: Vgs(Io) has been find from simulation | B38: Vgs(Io) | C38: 4.56 | D38: V
A39: Vgs th datasheet | B39: Vg th | C39: 2 | D39: V
A41: Time drain current fall: | B41: tfi | C41: =C5*(C38-C39)/C37 -> 4.4521739e-08 | D41: s
B42: Time total | C42: =C41+C24 -> 3.0452174e-07 | D42: s
A43: Off time loss: | B43: Poff loss | C43: =0.5*('Swtching loss'!C41+C24)*'IRFP4468PbF loss and tempurtur'!$B$13*'IRFP4468PbF loss and tempurtur'!$B$12*'IRFP4468PbF loss and tempurtur'!$B$27 -> 24.118122 | D43: W
A62: On time loss
A63: The time drain current fall is defined by Cgs and gate current | B63: I gate off | C63: =1.7/2 -> 0.85 | D63: A
A64: Vgs(Io) has been find from simulation | B64: Vgs(Io) | C64: 4.56 | D64: V
A65: Vgs th datasheet | B65: Vg th | C65: 2 | D65: V
A67: Time drain current rasi: | B67: tri | C67: =C5*(C38-C37)/C63 -> 8.0235294e-08 | D67: s
B68: Time total | C68: =C67+C23 -> 3.1023529e-07 | D68: s
A69: Off time loss: | B69: Poff loss | C69: =0.5*(C67+C23)*'IRFP4468PbF loss and tempurtur'!$B$12*'IRFP4468PbF loss and tempurtur'!$B$13*'IRFP4468PbF loss and tempurtur'!$B$27 -> 24.570635 | D69: W
A87: Total Sw loss
B89: P sw total | C89: =C69+C43 -> 48.688757 | D89: W

Sheet Max power time
A1: Max speed | B1: 50 | C1: km/t
B2: =B1/3.6 -> 13.888889 | C2: m/s
A4: mass | B4: 250 | C4: kg
A6: Torque from motor | B6: 30 | C6: Nm
A8: Gear care | B8: 12
A9: Gear wheel | B9: 50
A10: Gear ratio | B10: =B8/B9 -> 0.24
A12: Torque to wheel | B12: =B6/B10 -> 125 | C12: Nm
A14: Wheel Radius | B14: 5.5 | C14: "
B15: =B14*0.0254 -> 0.1397 | C15: m
A17: Force on wheel | B17: =B12/B15 -> 894.77452 | C17: N
A19: Acceleration | B19: =B17/B4 -> 3.5790981 | C19: m/s^2
A21: Time before max speed | B21: =B2/B19 -> 3.8805556 | C21: s
A22: ≈ | B22: 5 | C22: s
A24: For explanation see notes

Sheet Nominal current in MOSFET
A1: Assume that the only torque load when at max speed is air drag
A3: Area of air drag | B3: =1*0.4+0.5*0.4 -> 0.6 | C3: m^2
A4: dimension number (C) | B4: 0.804
A5: Air density | B5: 1.3 | C5: kg/m^2
A6: Max speed | B6: ='Max power time'!B1 -> 50 | C6: km/t
A7: Max speed | B7: ='Max power time'!B2 -> 13.888889 | C7: m/s
A9: Air drag force | B9: =0.5*B7^2*B5*B4*B3 -> 60.486111 | C9: N
A11: Torque on wheel | B11: =B9*'Max power time'!B15 -> 8.4499097 | C11: Nm
A12: Gear ratio | B12: ='Max power time'!B10 -> 0.24
A13: Torque from motor | B13: =B11*B12 -> 2.0279783 | C13: Nm
A15: Torque phas peak current rario
A16: Max torque | B16: 38 | C16: Nm
A17: Max phas peak current | B17: 300 | C17: A peak
A18: Kt | B18: =B16/B17 -> 0.12666667 | C18: Nm/A
A20: Phase current
A21: Peak | B21: =B13/B18 -> 16.010355 | C21: A peak
A22: RMS current | B22: =B21/2^0.5 -> 11.321031 | C22: A RMS

Sheet Ark1
A3: Lw | B3: 1e-07 | C3: H
A4: Cm | B4: =0.00012*3 -> 0.00036 | C4: F
A5: n | B5: 1
A6: Cd | B6: =B5*B4 -> 0.00036 | C6: F
A7: Rd | B7: =(B5+1)/B5*B3/(B4*B3)^0.5*(2*B5^2*(4+B5)/((2+B5)*(4+3*B5)))^0.5 -> 0.023002185 | C7: Ω
